<?xml version="1.0" ?>
<!-- =================================================================================== -->
<!-- |    This document was autogenerated by xacro from ./xarm_description/urdf/lite6/lite6.urdf.xacro | -->
<!-- |    EDITING THIS FILE BY HAND IS NOT RECOMMENDED                                 | -->
<!-- =================================================================================== -->
<robot name="lite6">
  <material name="White">
    <color rgba="1.0 1.0 1.0 1.0"/>
  </material>
  <material name="Red">
    <color rgba="1.0 0.0 0.0 1.0"/>
  </material>
  <material name="Blue">
    <color rgba="0.0 0.0 1.0 1.0"/>
  </material>
  <material name="Green">
    <color rgba="0.0 1.0 0.0 1.0"/>
  </material>
  <material name="Silver">
    <color rgba="0.753 0.753 0.753 1.0"/>
  </material>
  
  <link name="link_base">
    <inertial>
      <origin rpy="0 0 0" xyz="-0.00829544579053192 3.26357432323433E-05 0.0631194584987089"/>
      <mass value="1.65393501783165"/>
      <inertia ixx="0" ixy="0" ixz="0" iyy="0" iyz="0" izz="0"/>
    </inertial>
    <visual>
      <origin rpy="0 0 0" xyz="0 0 0.0"/>
      <geometry>
        <mesh filename="../meshes/visual/base.stl"/>
      </geometry>
      <material name="Red"/>
    </visual>
    <collision>
      <origin rpy="0 0 0" xyz="0 0 0.0"/>
      <geometry>
        <mesh filename="../meshes/visual/base.stl"/>
      </geometry>
    </collision>
  </link>
  <link name="link1">
    <inertial>
      <origin rpy="0 0 0" xyz="-0.00036 0.03788 -0.0027"/>
      <mass value="1.169"/>
      <inertia ixx="1.45164E-03" ixy="1.24E-05" ixz="-6.7E-06" iyy="8.873E-04" iyz="1.255E-04" izz="1.31993E-03"/>
    </inertial>
    <visual>
      <origin rpy="0 0 0" xyz="0 0 0.0"/>
      <geometry>
        <mesh filename="../meshes/visual/link1.stl"/>
      </geometry>
      <material name="Green"/>
    </visual>
    <collision>
      <origin rpy="0 0 0" xyz="0 0 0.0"/>
      <geometry>
        <mesh filename="../meshes/visual/link1.stl"/>
      </geometry>
    </collision>
  </link>
  <joint name="joint1" type="revolute">
    <origin rpy="0 0 0" xyz="0 0 0.2435"/>
    <parent link="link_base"/>
    <child link="link1"/>
    <axis xyz="0 0 1"/>
    <limit effort="50.0" lower="-6.283185307179586" upper="6.283185307179586" velocity="3.14"/>
    <dynamics damping="0.01" friction="1.0"/>
  </joint>
  <link name="link2">
    <inertial>
      <origin rpy="0 0 0" xyz="0.178 0.0 0.0576"/>
      <mass value="1.192"/>
      <inertia ixx="1.5854E-03" ixy="-6.766E-06" ixz="-1.15136E-03" iyy="5.6097E-03" iyz="1.14E-06" izz="4.85E-03"/>
    </inertial>
    <visual>
      <origin rpy="0 0 0" xyz="0 0 0"/>
      <geometry>
        <mesh filename="../meshes/visual/link2.stl"/>
      </geometry>
      <material name="Blue"/>
    </visual>
    <collision>
      <origin rpy="0 0 0" xyz="0 0 0"/>
      <geometry>
        <mesh filename="../meshes/visual/link2.stl"/>
      </geometry>
    </collision>
  </link>
  <joint name="joint2" type="revolute">
    <origin rpy="1.5708 -1.5708 3.1416" xyz="0 0.005 0.0"/>
    <parent link="link1"/>
    <child link="link2"/>
    <axis xyz="0 0 1"/>
    <limit effort="50.0" lower="-2.61799" upper="2.61799" velocity="3.14"/>
    <dynamics damping="0.01" friction="1.0"/>
  </joint>
  <link name="link3">
    <inertial>
      <origin rpy="0 0 0" xyz="0.07285 -0.030 -0.0009"/>
      <mass value="0.930"/>
      <inertia ixx="8.861E-04" ixy="-3.9287E-04" ixz="7.066E-05" iyy="1.5785E-03" iyz="-2.445E-05" izz="1.84677E-03"/>
    </inertial>
    <visual>
      <origin rpy="0 0 0" xyz="0 0 0"/>
      <geometry>
        <mesh filename="../meshes/visual/link3.stl"/>
      </geometry>
      <material name="Red"/>
    </visual>
    <collision>
      <origin rpy="0 0 0" xyz="0 0 0"/>
      <geometry>
        <mesh filename="../meshes/visual/link3.stl"/>
      </geometry>
    </collision>
  </link>
  <joint name="joint3" type="revolute">
    <origin rpy="-3.1416 0 1.5708" xyz="0.2002 0 0"/>
    <parent link="link2"/>
    <child link="link3"/>
    <axis xyz="0 0 1"/>
    <limit effort="32.0" lower="-0.061087" upper="5.235988" velocity="3.14"/>
    <dynamics damping="0.01" friction="1.0"/>
  </joint>
  <link name="link4">
    <inertial>
      <origin rpy="0 0 0" xyz="-0.0004 -0.0275 -0.0817"/>
      <mass value="1.31"/>
      <inertia ixx="3.705E-03" ixy="-2.0E-06" ixz="7.17E-06" iyy="3.0455E-03" iyz="-9.3188E-04" izz="1.5413E-03"/>
    </inertial>
    <visual>
      <origin rpy="0 0 0" xyz="0 0 0"/>
      <geometry>
        <mesh filename="../meshes/visual/link4.stl"/>
      </geometry>
      <material name="Green"/>
    </visual>
    <collision>
      <origin rpy="0 0 0" xyz="0 0 0"/>
      <geometry>
        <mesh filename="../meshes/visual/link4.stl"/>
      </geometry>
    </collision>
  </link>
  <joint name="joint4" type="revolute">
    <origin rpy="1.5708 0 0" xyz="0.087 -0.22761 0"/>
    <parent link="link3"/>
    <child link="link4"/>
    <axis xyz="0 0 1"/>
    <limit effort="32.0" lower="-6.283185307179586" upper="6.283185307179586" velocity="3.14"/>
    <dynamics damping="0.01" friction="1.0"/>
  </joint>
  <link name="link5">
    <inertial>
      <origin rpy="0 0 0" xyz="0.0 0.010 0.0019"/>
      <mass value="0.784"/>
      <inertia ixx="5.668E-04" ixy="6E-07" ixz="-5.3E-06" iyy="5.077E-04" iyz="-4.8E-07" izz="5.3E-04"/>
    </inertial>
    <visual>
      <origin rpy="0 0 0" xyz="0 0 0"/>
      <geometry>
        <mesh filename="../meshes/visual/link5.stl"/>
      </geometry>
      <material name="Blue"/>
    </visual>
    <collision>
      <origin rpy="0 0 0" xyz="0 0 0"/>
      <geometry>
        <mesh filename="../meshes/visual/link5.stl"/>
      </geometry>
    </collision>
  </link>
  <joint name="joint5" type="revolute">
    <origin rpy="1.5708 0 0" xyz="0 0 0"/>
    <parent link="link4"/>
    <child link="link5"/>
    <axis xyz="0 0 1"/>
    <limit effort="32.0" lower="-2.1642" upper="2.1642" velocity="3.14"/>
    <dynamics damping="0.01" friction="1.0"/>
  </joint>
  <link name="link6">
    <inertial>
      <origin rpy="0 0 0" xyz="0.0 -0.00194 -0.0102"/>
      <mass value="0.180"/>
      <inertia ixx="7.726E-05" ixy="1E-06" ixz="4E-07" iyy="8.5665E-05" iyz="-6E-07" izz="1.4814E-04"/>
    </inertial>
    <visual>
      <origin rpy="0 0 0" xyz="0 0 0"/>
      <geometry>
        <mesh filename="../meshes/visual/link6.stl"/>
      </geometry>
      <material name="Silver"/>
    </visual>
    <collision>
      <origin rpy="0 0 0" xyz="0 0 0"/>
      <geometry>
        <mesh filename="../meshes/visual/link6.stl"/>
      </geometry>
    </collision>
  </link>
  <joint name="joint6" type="revolute">
    <origin rpy="-1.5708 0 0" xyz="0 0.0625 0"/>
    <parent link="link5"/>
    <child link="link6"/>
    <axis xyz="0 0 1"/>
    <limit effort="20.0" lower="-6.283185307179586" upper="6.283185307179586" velocity="3.14"/>
    <dynamics damping="0.01" friction="1.0"/>
  </joint>
  <link name="link_eef"/>
  <joint name="joint_eef" type="fixed">
    <origin rpy="0 0 0" xyz="0 0 0"/>
    <parent link="link6"/>
    <child link="link_eef"/>
  </joint>
  
    
  <!--###### SOPORTES ######-->
  <link name="soporte_base_link">
    <visual>
      <origin rpy="0 0 0" xyz="0 0 0"/>
      <geometry>
        <mesh filename="../world/soporte1_escalado.obj"/>
      </geometry>
      <material name="Silver"/>
    </visual>
    <collision>
      <origin rpy="0 0 0" xyz="0 0 0"/>
      <geometry>
        <mesh filename="../world/soporte1_escalado.obj"/>
      </geometry>
    </collision>
    <inertial>
      <mass value="0.5"/>
      <origin rpy="0 0 0" xyz="0 0 0"/>
      <inertia ixx="0.001" ixy="0" ixz="0" iyy="0.001" iyz="0" izz="0.001"/>
    </inertial>
  </link>
  
  <joint name="soporte_base_joint" type="fixed">
    <parent link="link_base"/>
    <child link="soporte_base_link"/>
    <origin rpy="3.1416 0 0" xyz="0.0 0.18 0.05"/>
  </joint>
  
  <link name="soporte_2_link">
    <visual>
      <origin rpy="0 0 0" xyz="0 0 0"/>
      <geometry>
        <mesh filename="../world/soporte2_escalado.obj"/>
      </geometry>
      <material name="Silver"/>
    </visual>
    <collision>
      <origin rpy="0 0 0" xyz="0 0 0"/>
      <geometry>
        <mesh filename="../world/soporte2_escalado.obj"/>
      </geometry>
    </collision>
    <inertial>
      <mass value="0.5"/>
      <origin rpy="0 0 0" xyz="0 0 0"/>
      <inertia ixx="0.001" ixy="0" ixz="0" iyy="0.001" iyz="0" izz="0.001"/>
    </inertial>
  </link>
  
  <joint name="soporte_2_joint" type="fixed">
    <parent link="link2"/>
    <child link="soporte_2_link"/>
    <origin rpy="-1.5708 0 0" xyz="0.08 0.0 0.175"/>
  </joint>
  
  <link name="soporte_4_link">
    <visual>
      <origin rpy="0 0 0" xyz="0 0 0"/>
      <geometry>
        <mesh filename="../world/soporte2_escalado.obj"/>
      </geometry>
      <material name="Silver"/>
    </visual>
    <collision>
      <origin rpy="0 0 0" xyz="0 0 0"/>
      <geometry>
        <mesh filename="../world/soporte2_escalado.obj"/>
      </geometry>
    </collision>
    <inertial>
      <mass value="0.5"/>
      <origin rpy="0 0 0" xyz="0 0 0"/>
      <inertia ixx="0.001" ixy="0" ixz="0" iyy="0.001" iyz="0" izz="0.001"/>
    </inertial>
  </link>
  
  <joint name="soporte_4_joint" type="fixed">
    <parent link="link4"/>
    <child link="soporte_4_link"/>
    <origin rpy="0 0 0" xyz="0.0 -0.175 0.0"/>
  </joint>
  <!--###### SOPORTES ######-->
</robot>
